<?xml version="1.0" encoding="UTF-8"?>

<robot name="wheel" xmlns:xacro="http://www.ros.org/wiki/xacro">

  <xacro:property name="wheel_mass" value="2.166" /> <!-- in kg-->
  <xacro:property name="pi" value="3.14159"/>

  <xacro:property name="caster_joint_damping" value="1.0"/>
  <xacro:property name="caster_joint_friction" value="1.0"/>
  <xacro:property name="caster_joint_effort" value="30"/>
  <xacro:property name="caster_joint_velocity" value="10"/>
  <xacro:property name="caster_joint_safety_k_velocity" value="10.0"/>

  <xacro:property name="wheel_joint_damping" value="1.0"/>
  <xacro:property name="wheel_joint_friction" value="1.0"/>
  <xacro:property name="wheel_joint_effort" value="30"/>
  <xacro:property name="wheel_joint_velocity" value="10"/>
  <xacro:property name="wheel_joint_safety_k_velocity" value="10.0"/>

  <xacro:property name="wheel_mechanical_reduction" value="${624/35 * 80/18}" />
  <xacro:property name="caster_mechanical_reduction" value="${624/35 * 80/18}" />
 
 
  <xacro:macro name="mecanum_inertia">
    <inertia  ixx="0.008" ixy = "0" ixz = "0"
              iyy="0.008" iyz = "0"
              izz="0.010" /> 
  </xacro:macro>

  <xacro:macro name="mecanum_wheel_youbot_collision" params="prefix angle wheel_pos parent">
  
  
    <joint name="${prefix}_caster_joint_collision" type="continuous">
      <parent link="${parent}"/>
      <child link="${prefix}_caster_link"/>
      <xacro:if value="${prefix == 'agv_front_left'}">
      	<origin xyz="0.835 0.316 0.103" /> <!-- y = 0.213 -->
      </xacro:if>
      <xacro:if value="${prefix == 'agv_front_right'}">
      	<origin xyz="0.835 -0.364 0.103" /> <!-- y = -0.261 -->
      </xacro:if>
      <xacro:if value="${prefix == 'agv_back_left'}">
      	<origin xyz="0.125 0.317 0.102" /> <!-- y = 0.214 -->
      </xacro:if>
      <xacro:if value="${prefix == 'agv_back_right'}">
      	<origin xyz="0.125 -0.365 0.102" /> <!-- y = -0.262 -->
      </xacro:if>
      <axis xyz="0 0 1" rpy="0 0 0" />
      <limit effort="${caster_joint_effort}" velocity="${caster_joint_velocity}"/>
      <dynamics damping="${caster_joint_damping}" friction="${caster_joint_friction}"/>
      <safety_controller k_velocity="${caster_joint_safety_k_velocity}"/>
    </joint>

    <link name="${prefix}_caster_link">
      <inertial>
        <mass value="0.1"/>
        <origin xyz="0 0 0"/>
        <inertia ixx="0.012411765597" ixy="-0.000711733678" ixz="0.00050272983" iyy="0.015218160428" iyz="-0.000004273467" izz="0.011763977943"/>
      </inertial>
    </link>

    <joint name="${prefix}_wheel_joint_collision" type="continuous">
      <parent link="${prefix}_caster_link"/>
      <child link="${prefix}_wheel_link_collision"/>
      <origin xyz="0.0 0.0 0.0" />
      <axis xyz="0 1 0" rpy="0 0 0" />
      <limit effort="${wheel_joint_effort}" velocity="${wheel_joint_velocity}"/>
      <dynamics damping="${wheel_joint_damping}" friction="${wheel_joint_friction}"/>
      <safety_controller k_velocity="${wheel_joint_safety_k_velocity}"/>
    </joint>
  
    <link name="${prefix}_wheel_link_collision">
      <collision>
	<origin xyz="0 0 0" rpy="${pi*angle/2} 0 0" />
        <geometry>
	 <sphere radius="0.103"/>
<!--	  <mesh filename="package://agv_low/meshes/agv_sphere_wheel.stl"/> -->
	</geometry>
      </collision>
<!--      <visual>
	<origin xyz="0 0 0" rpy="${pi*angle/2} 0 0" />
        <geometry>
	 <sphere radius="0.103"/>
	  <mesh filename="package://agv_low/meshes/agv_sphere_wheel.stl"/>
	</geometry>
      </visual>
-->
      <inertial>
        <mass value="${wheel_mass}" />
        <origin xyz="0 0 0" />
        <xacro:mecanum_inertia />
      </inertial>
    </link>
    
    <!-- Transmission is important to link the joints and the controller-->

    <transmission name="${prefix}_wheel_joint_collision_trans">
      <type>transmission_interface/SimpleTransmission</type>
      <actuator name="${prefix}_wheel_joint_collision_motor">
        <hardwareInterface>hardware_interface/VelocityJointInterface</hardwareInterface>
        <mechanicalReduction>${wheel_mechanical_reduction}</mechanicalReduction>
      </actuator>
      <joint name="${prefix}_wheel_joint_collision">
        <hardwareInterface>hardware_interface/VelocityJointInterface</hardwareInterface>
      </joint>
    </transmission>

    <transmission name="${prefix}_caster_joint_collision_trans">
      <type>transmission_interface/SimpleTransmission</type>
       <actuator name="${prefix}_caster_joint_collision_motor">
        <hardwareInterface>hardware_interface/VelocityJointInterface</hardwareInterface>
        <mechanicalReduction>${caster_mechanical_reduction}</mechanicalReduction>
      </actuator>
      <joint name="${prefix}_caster_joint_collision">
        <hardwareInterface>hardware_interface/VelocityJointInterface</hardwareInterface>
      </joint>
    </transmission>
    
    <gazebo reference="${prefix}_wheel_link_collision">
		<mu1 value="1.0"/>
		<mu2 value="1.0"/>
		<kp value="1000000.0" />
		<kd value="1.0" />
		<fdir1 value="1 0 0"/>
      <turnGravityOff>false</turnGravityOff>
    </gazebo>
     
  </xacro:macro>

</robot>
