<?xml version="1.0" encoding="UTF-8"?>

<robot name="wheel" xmlns:xacro="http://www.ros.org/wiki/xacro">

  <xacro:property name="wheel_mass" value="2" /> <!-- 2.166 in kg-->
  <xacro:property name="pi" value="3.14159"/>
  <xacro:property name="wheel_joint_damping" value="1.0"/>
  <xacro:property name="wheel_joint_friction" value="1.0"/>
  <xacro:property name="wheel_joint_effort" value="30"/>
  <xacro:property name="wheel_joint_velocity" value="10"/>
  <xacro:property name="wheel_joint_safety_k_velocity" value="10.0"/>
  <xacro:property name="wheel_mechanical_reduction" value="${624/35 * 80/18}" />
 
  <xacro:macro name="mecanum_inertia">
    <inertia  ixx="0.0085" ixy = "0" ixz = "0"
              iyy="0.0085" iyz = "0"
              izz="0.0085" /> 
  </xacro:macro>

  <xacro:macro name="mecanum_wheel_visual" params="prefix angle wheel_pos parent">
  
  
    <joint name="${prefix}_wheel_joint_visual" type="continuous">
      <parent link="${parent}"/>
      <child link="${prefix}_wheel_link_visual"/>
<!--
      <xacro:if value="${prefix == 'agv_front_left'}">
      	<origin xyz="0.835 0.213 0.103" />
      </xacro:if>
      <xacro:if value="${prefix == 'agv_front_right'}">
      	<origin xyz="0.835 -0.261 0.103" />
      </xacro:if>
      <xacro:if value="${prefix == 'agv_back_left'}">
      	<origin xyz="0.125 0.214 0.102" />
      </xacro:if>
      <xacro:if value="${prefix == 'agv_back_right'}">
      	<origin xyz="0.125 -0.262 0.102" />
      </xacro:if>
-->
      <xacro:if value="${prefix == 'agv_front_left'}">
      	<origin xyz="0.355 0.237 -0.236" /> <!-- y = 0.213     0.355 0.237 -0.236 -->
      </xacro:if>
      <xacro:if value="${prefix == 'agv_front_right'}">
      	<origin xyz="0.355 -0.237 -0.236" /> <!-- y = -0.261 -->
      </xacro:if>
      <xacro:if value="${prefix == 'agv_back_left'}">
      	<origin xyz="-0.355 0.238 -0.236" /> <!-- y = 0.214 -->
      </xacro:if>
      <xacro:if value="${prefix == 'agv_back_right'}">
      	<origin xyz="-0.355 -0.238 -0.236" /> <!-- y = -0.262 -->
      </xacro:if>
      <axis xyz="0 1 0" rpy="0 0 0" />
      <limit effort="${wheel_joint_effort}" velocity="${wheel_joint_velocity}"/>
      <dynamics damping="${wheel_joint_damping}" friction="${wheel_joint_friction}"/>
      <safety_controller k_velocity="${wheel_joint_safety_k_velocity}"/>
    </joint>
  
    <link name="${prefix}_wheel_link_visual">
      <visual>
      	<origin xyz="0 0 0" rpy="${pi*angle/2} 0 0" />
          <xacro:if value="${wheel_pos}">
            <geometry>     
              <mesh filename="package://agv_low/meshes/Radbefestigung mit Motor-Getrieb (LVA33)_wheels_simplified_mesh.stl" />
            </geometry>          
          </xacro:if>
          <xacro:unless value="${wheel_pos}">
            <geometry>     
              <mesh filename="package://agv_low/meshes/Radbefestigung mit Motor-Getrieb (LVA33)_MIR_wheels_simplified_mesh.stl" />
            </geometry>			  
	  </xacro:unless>     	      
      </visual>
      <inertial>
        <mass value="${wheel_mass}" />
        <origin xyz="0 0 0.076" /> <!-- "0 0 0.076" -->
        <xacro:mecanum_inertia />
      </inertial>
    </link>
<!--    
    <transmission name="${prefix}_wheel_joint_visual_trans">
      <type>transmission_interface/SimpleTransmission</type>
      <actuator name="${prefix}_wheel_joint_visual_motor">
        <hardwareInterface>hardware_interface/VelocityJointInterface</hardwareInterface>
        <mechanicalReduction>${wheel_mechanical_reduction}</mechanicalReduction>
      </actuator>
      <joint name="${prefix}_wheel_joint_visual">
        <hardwareInterface>hardware_interface/VelocityJointInterface</hardwareInterface>
      </joint>
    </transmission>
-->
    <gazebo reference="${prefix}_wheel_link_visual">
		<mu1 value="1.0"/>
		<mu2 value="1.0"/>
		<kp value="10000000.0" />
		<kd value="1.0" />
		<fdir1 value="1 0 0"/>
		<material>Gazebo/Grey</material>
      <turnGravityOff>false</turnGravityOff>
    </gazebo>
     
  </xacro:macro>

</robot>
