<?xml version="1.0"?>
<robot name="base" xmlns:xacro="http://www.ros.org/wiki/xacro">

	<xacro:property name="wheel_joint_damping" value="1.0"/>
  	<xacro:property name="wheel_joint_friction" value="1.0"/>
  	<xacro:property name="wheel_joint_effort" value="30"/>
  	<xacro:property name="wheel_joint_velocity" value="10"/>
  	<xacro:property name="wheel_joint_safety_k_velocity" value="10.0"/>
  
	<link name="base_footprint">
		<visual>
			<origin xyz="0 0 0" rpy="0 0 0" /> <!-- "0.48 -0.0245 0.27" -->
			<geometry>
				<box size="0.001 0.001 0.001" />
			</geometry>
		</visual>
	</link>
	
	<joint name="base_footprint_joint" type="fixed">
		<origin xyz="0 0 0" rpy="0 0 0" /> <!-- "0.48 -0.0245 0" -->
		<parent link="base_footprint"/>
		<child link="base_link" />
	</joint>
	
	<link name="base_link">
    <visual>
      <geometry>
        <box size="0.6 0.3 0.2"/>
      </geometry>
    </visual>
    <collision>
      <geometry>
        <box size="0.6 0.3 0.2"/>
      </geometry>
    </collision>
    <inertial>
    	<origin rpy="0 0 0" xyz="0 0 0"/>
    	<mass value="36.0"/>
    	<inertia ixx="1.2" ixy="0.0" ixz="0.0" iyy="1.350" iyz="0.0" izz="0.390"/>
  	 </inertial>
  	</link>
  	
  	<joint name="wheel_joint_left" type="continuous">
      <parent link="base_link"/>
      <child link="wheel_link_left"/>
      <origin xyz="0.0 0.0 0.0" />
      <axis xyz="0 1 0" rpy="0 0 0" />
      <limit effort="${wheel_joint_effort}" velocity="${wheel_joint_velocity}"/>
      <dynamics damping="${wheel_joint_damping}" friction="${wheel_joint_friction}"/>
      <safety_controller k_velocity="${wheel_joint_safety_k_velocity}"/>
    </joint>
    
  	<link name="wheel_link_left">
   	<collision>
			<origin xyz="-0.1 -0.253 0" rpy="0 0 0" />
    		<geometry>
	  			<sphere radius="0.103"/>
	 		</geometry>
      </collision>
      <visual>
			<origin xyz="-0.1 -0.253 0" rpy="0 0 0" />
        	<geometry>
	 			<sphere radius="0.103"/>
			</geometry>
      </visual>
      <inertial>
        <mass value="2" />
        <origin xyz="0 0 0" />
        <inertia ixx="0.0085" ixy="0.0" ixz="0.0" iyy="0.0085" iyz="0.0" izz="0.0085"/>
      </inertial>
    </link>
    
    <joint name="wheel_joint_right" type="continuous">
      <parent link="base_link"/>
      <child link="wheel_link_right"/>
      <origin xyz="0.0 0.0 0.0" />
      <axis xyz="0 1 0" rpy="0 0 0" />
      <limit effort="${wheel_joint_effort}" velocity="${wheel_joint_velocity}"/>
      <dynamics damping="${wheel_joint_damping}" friction="${wheel_joint_friction}"/>
      <safety_controller k_velocity="${wheel_joint_safety_k_velocity}"/>
    </joint>
    
  	<link name="wheel_link_right">
   	<collision>
			<origin xyz="-0.1 0.253 0" rpy="0 0 0" />
    		<geometry>
	  			<sphere radius="0.103"/>
	 		</geometry>
      </collision>
      <visual>
			<origin xyz="-0.1 0.253 0" rpy="0 0 0" />
        	<geometry>
	 			<sphere radius="0.103"/>
			</geometry>
      </visual>
      <inertial>
        <mass value="2" />
        <origin xyz="0 0 0" />
        <inertia ixx="0.0085" ixy="0.0" ixz="0.0" iyy="0.0085" iyz="0.0" izz="0.0085"/>
      </inertial>
    </link>
    
    <joint name="base_footprint_joint" type="fixed">
		<origin xyz="0 0 0" rpy="0 0 0" /> <!-- "0.48 -0.0245 0" -->
		<parent link="base_link"/>
		<child link="wheel_link_fixed" />
	</joint>
	
	<link name="wheel_link_fixed">
   	<collision>
			<origin xyz="0.1 0 0" rpy="0 0 0" />
    		<geometry>
	  			<sphere radius="0.103"/>
	 		</geometry>
      </collision>
      <visual>
			<origin xyz="0.1 0 0" rpy="0 0 0" />
        	<geometry>
	 			<sphere radius="0.103"/>
			</geometry>
      </visual>
      <inertial>
        <mass value="2" />
        <origin xyz="0 0 0" />
        <inertia ixx="0.0085" ixy="0.0" ixz="0.0" iyy="0.0085" iyz="0.0" izz="0.0085"/>
      </inertial>
    </link>
    <gazebo>
  		<plugin name="differential_drive_controller" filename="libgazebo_ros_diff_drive.so"> <!-- libdiff_drive.so -->
			<alwaysOn>true</alwaysOn>
    		<updateRate>10</updateRate>
    		<leftJoint>wheel_joint_left</leftJoint>
    		<rightJoint>wheel_joint_right</rightJoint>
			<wheelSeparation>0.6</wheelSeparation>
    		<wheelDiameter>0.206</wheelDiameter>
    		<torque>20</torque>
   		<commandTopic>cmd_vel</commandTopic>
   		<odometryTopic>odom</odometryTopic>
   		<odometryFrame>odom</odometryFrame>
   		<robotBaseFrame>base_footprint</robotBaseFrame> 
   	</plugin> 
   </gazebo>
    
</robot>

